[2025-10-04T13:42:49.426+0000] {task_context_logger.py:104} ERROR - Executor reports task instance <TaskInstance: retail_mlops_data_pipeline.process_data_and_train_model scheduled__2025-10-03T00:00:00+00:00 [queued]> finished (failed) although the task says it's queued. (Info: None) Was the task killed externally?
