[2025-10-04T13:57:15.129+0000] {task_context_logger.py:104} ERROR - Executor reports task instance <TaskInstance: retail_mlops_data_pipeline.create_data_directory manual__2025-10-04T13:57:12.974491+00:00 [queued]> finished (failed) although the task says it's queued. (Info: None) Was the task killed externally?
