[2025-10-04T17:09:42.235+0000] {local_task_job_runner.py:120} INFO - ::group::Pre task execution logs
[2025-10-04T17:09:42.249+0000] {taskinstance.py:2073} INFO - Dependencies all met for dep_context=non-requeueable deps ti=<TaskInstance: retail_mlops_data_pipeline.download_raw_data_kaggle manual__2025-10-04T16:56:50.000373+00:00 [queued]>
[2025-10-04T17:09:42.253+0000] {taskinstance.py:2073} INFO - Dependencies all met for dep_context=requeueable deps ti=<TaskInstance: retail_mlops_data_pipeline.download_raw_data_kaggle manual__2025-10-04T16:56:50.000373+00:00 [queued]>
[2025-10-04T17:09:42.253+0000] {taskinstance.py:2303} INFO - Starting attempt 4 of 4
[2025-10-04T17:09:42.270+0000] {taskinstance.py:2327} INFO - Executing <Task(PythonOperator): download_raw_data_kaggle> on 2025-10-04 16:56:50.000373+00:00
[2025-10-04T17:09:42.276+0000] {standard_task_runner.py:63} INFO - Started process 12162 to run task
[2025-10-04T17:09:42.279+0000] {standard_task_runner.py:90} INFO - Running: ['airflow', 'tasks', 'run', 'retail_mlops_data_pipeline', 'download_raw_data_kaggle', 'manual__2025-10-04T16:56:50.000373+00:00', '--job-id', '33', '--raw', '--subdir', 'DAGS_FOLDER/retail_mlops_data_pipeline.py', '--cfg-path', '/tmp/tmp3x0z_sb8']
[2025-10-04T17:09:42.280+0000] {standard_task_runner.py:91} INFO - Job 33: Subtask download_raw_data_kaggle
[2025-10-04T17:09:42.318+0000] {task_command.py:426} INFO - Running <TaskInstance: retail_mlops_data_pipeline.download_raw_data_kaggle manual__2025-10-04T16:56:50.000373+00:00 [running]> on host ip-172-31-17-35.ec2.internal
[2025-10-04T17:09:42.372+0000] {taskinstance.py:2644} INFO - Exporting env vars: AIRFLOW_CTX_DAG_OWNER='airflow' AIRFLOW_CTX_DAG_ID='retail_mlops_data_pipeline' AIRFLOW_CTX_TASK_ID='download_raw_data_kaggle' AIRFLOW_CTX_EXECUTION_DATE='2025-10-04T16:56:50.000373+00:00' AIRFLOW_CTX_TRY_NUMBER='4' AIRFLOW_CTX_DAG_RUN_ID='manual__2025-10-04T16:56:50.000373+00:00'
[2025-10-04T17:09:42.373+0000] {taskinstance.py:430} INFO - ::endgroup::
[2025-10-04T17:09:42.386+0000] {logging_mixin.py:188} INFO - Starting download of mehmettahiraslan/customer-shopping-dataset...
[2025-10-04T17:09:42.387+0000] {taskinstance.py:441} INFO - ::group::Post task execution logs
[2025-10-04T17:09:42.388+0000] {taskinstance.py:2890} ERROR - Task failed with exception
Traceback (most recent call last):
  File "/root/airflow_venv/lib/python3.12/site-packages/airflow/models/taskinstance.py", line 465, in _execute_task
    result = _execute_callable(context=context, **execute_callable_kwargs)
             ^^^^^^^^^^^^^^^^^^^^^^^^^^^^^^^^^^^^^^^^^^^^^^^^^^^^^^^^^^^^^
  File "/root/airflow_venv/lib/python3.12/site-packages/airflow/models/taskinstance.py", line 432, in _execute_callable
    return execute_callable(context=context, **execute_callable_kwargs)
           ^^^^^^^^^^^^^^^^^^^^^^^^^^^^^^^^^^^^^^^^^^^^^^^^^^^^^^^^^^^^
  File "/root/airflow_venv/lib/python3.12/site-packages/airflow/models/baseoperator.py", line 400, in wrapper
    return func(self, *args, **kwargs)
           ^^^^^^^^^^^^^^^^^^^^^^^^^^^
  File "/root/airflow_venv/lib/python3.12/site-packages/airflow/operators/python.py", line 235, in execute
    return_value = self.execute_callable()
                   ^^^^^^^^^^^^^^^^^^^^^^^
  File "/root/airflow_venv/lib/python3.12/site-packages/airflow/operators/python.py", line 252, in execute_callable
    return self.python_callable(*self.op_args, **self.op_kwargs)
           ^^^^^^^^^^^^^^^^^^^^^^^^^^^^^^^^^^^^^^^^^^^^^^^^^^^^^
  File "/root/airflow/dags/retail_mlops_data_pipeline.py", line 47, in download_data
    subprocess.run([
  File "/usr/lib/python3.12/subprocess.py", line 548, in run
    with Popen(*popenargs, **kwargs) as process:
         ^^^^^^^^^^^^^^^^^^^^^^^^^^^
  File "/usr/lib/python3.12/subprocess.py", line 1026, in __init__
    self._execute_child(args, executable, preexec_fn, close_fds,
  File "/usr/lib/python3.12/subprocess.py", line 1955, in _execute_child
    raise child_exception_type(errno_num, err_msg, err_filename)
FileNotFoundError: [Errno 2] No such file or directory: 'kaggle'
[2025-10-04T17:09:42.392+0000] {taskinstance.py:1205} INFO - Marking task as FAILED. dag_id=retail_mlops_data_pipeline, task_id=download_raw_data_kaggle, execution_date=20251004T165650, start_date=20251004T170942, end_date=20251004T170942
[2025-10-04T17:09:42.408+0000] {standard_task_runner.py:110} ERROR - Failed to execute job 33 for task download_raw_data_kaggle ([Errno 2] No such file or directory: 'kaggle'; 12162)
[2025-10-04T17:09:42.452+0000] {local_task_job_runner.py:240} INFO - Task exited with return code 1
[2025-10-04T17:09:42.469+0000] {taskinstance.py:3482} INFO - 0 downstream tasks scheduled from follow-on schedule check
[2025-10-04T17:09:42.479+0000] {local_task_job_runner.py:222} INFO - ::endgroup::
