[2025-10-04T13:42:52.991+0000] {task_context_logger.py:104} ERROR - Executor reports task instance <TaskInstance: retail_mlops_data_pipeline.process_data_and_train_model manual__2025-10-04T13:35:29.651358+00:00 [queued]> finished (failed) although the task says it's queued. (Info: None) Was the task killed externally?
